Workbook

Sheet Master Imaging list
A1: date_mount | B1: mount_id | C1: ZF female genotype | D1: ZF male genotype | E1: additional plasmids injected | F1: additional mRNAs injected | G1: additonal proteins injected | H1: additonal dye and chemicals | I1: Date born | J1: Time mounted | K1: Mounting Orientation | L1: Date screened/Initial feedback | M1: Date imaged | N1: Time placed in scope | O1: Start of imaging time | P1: End of imaging time | Q1: Imaged Locations | R1: Unique Targets with blanks | S1: Unique Targets | T1: Data location | U1: Dataset size (GB) - raw data only | V1: Camera Filters | W1: JSON excite map for ZF male | X1: JSON excite map for ZF female | Y1: JSON excite map for plasmid | Z1: JSON excite map for mRNA | AA1: comments | AB1: Data evaluation comments
A2: 46013 | B2: 1 | C2: ef1a:2xLynk:tdmSG(J) (F1 of allele 302) | D2: tdmScarlet3S2:H2B-tol2 (F1 of allele 324) | G2: None | H2: None | I2: 46010 | J2: 0.5 | K2: LHDH
A3: 46013 | B3: 2 | C3: ef1a:2xLynk:tdmSG(J) (F1 of allele 302) | D3: tdmScarlet3S2:H2B-tol2 (F1 of allele 324) | G3: None | H3: None | I3: 46010 | J3: 0.5 | K3: LHDH
A4: 46010 | B4: 1 | C4: casper | D4: casper | G4: None | H4: coral_rna_mix_120 | I4: 46009 | J4: 0.54166667 | K4: DH
A5: 46010 | B5: 2 | C5: casper | D5: casper | G5: None | H5: coral_rna_mix_600 | I5: 46009 | J5: 0.54166667 | K5: DH
A6: 46009 | B6: 1 | C6: ef1a:2xLynk:tdmSG(J) (F1 of allele 302) | D6: tdmScarlet3S2:H2B-tol2 (F1 of allele 324) | G6: None | H6: None | I6: 46006 | J6: 0.41666667 | K6: LHDH
A7: 46009 | B7: 2 | C7: ef1a:2xLynk:tdmSG(J) (F1 of allele 302) | D7: tdmScarlet3S2:H2B-tol2 (F1 of allele 324) | G7: None | H7: None | I7: 46006 | J7: 0.41666667 | K7: LHDH
A8: 46008 | B8: 1 | C8: ef1a:2xLynk:tdmSG(J) (F1 of allele 302) | D8: tdmScarlet3S2:H2B-tol2 (F1 of allele 324) | G8: None | H8: None | I8: 46006 | J8: 0.41666667 | K8: DH | M8: 46008 | Q8: muscle, notochord, spinal_cord, skin, tail, blood vessel | T8: X:\abcabc\Korra_Foundation\20251217_mem-histone
A9: 46008 | B9: 2 | C9: ef1a:2xLynk:tdmSG(J) (F1 of allele 302) | D9: tdmScarlet3S2:H2B-tol2 (F1 of allele 324) | G9: None | H9: None | I9: 46006 | J9: 0.41666667 | K9: DH | M9: 46008 | T9: X:\abcabc\Aang_Foundation\20251217_mem-histone
A10: 46007 | B10: 1 | C10: ef1a:2xLynk:tdmSG(J) (F1 of allele 301) | D10: tdmScarlet3S2:H2B-tol2 (F1 of allele 324) | G10: None | H10: None | I10: 46006 | J10: 0.41666667 | K10: DH | M10: 46007 | Q10: muscle, notochord, spinal_cord, skin, tail, blood vessel | T10: X:\abcabc\Aang_Foundation\20251216_mem-histone | U10: 5253
A11: 46007 | B11: 2 | C11: ef1a:2xLynk:tdmSG(J) (F1 of allele 301) | D11: tdmScarlet3S2:H2B-tol2 (F1 of allele 324) | G11: None | H11: None | I11: 46006 | J11: 0.41666667 | K11: DH | M11: 46007 | Q11: brain, skin, hindbrain, spinal_cord, muscle, notochord | T11: X:\abcabc\Korra_Foundation\20251216_mem-histone | U11: 5365
A12: 46003 | B12: 1 | C12: ef1a:2xLynk:tdmSG(J) (F1 of allele 302) | D12: tdmScarlet3S2:H2B-tol2 (F1 of allele 324) | G12: None | H12: None | I12: 45999 | J12: 0.41666667 | K12: LHDH | M12: 46003 | Q12: skin, muscle, tail, neuromast, notochord, blood vessel, spinal_cord, hindbrain | T12: X:\abcabc\Aang_Foundation\20251212_mem-histone | U12: 5530
A13: 46003 | B13: 2 | C13: ef1a:2xLynk:tdmSG(J) (F1 of allele 302) | D13: tdmScarlet3S2:H2B-tol2 (F1 of allele 324) | G13: None | H13: None | I13: 45999 | J13: 0.41666667 | K13: LHDH | M13: 46003 | Q13: skin, muscle, tail, neuromast, notochord, blood vessel, spinal_cord, hindbrain | T13: X:\abcabc\Korra_Foundation\20251212_mem-histone | U13: 11059
A14: 46002 | B14: 1 | C14: ef1a:2xLynk:tdmSG(J) (F1 of allele 302) | D14: tdmScarlet3S2:H2B-tol2 (F1 of allele 324) | G14: None | H14: None | I14: 45999 | J14: 0.41666667 | K14: LHDH | M14: 46002 | Q14: muscle, notochord, spinal_cord, skin, tail, blood vessel | T14: X:\abcabc\Korra_Foundation\20251211_mem-histone | U14: 4936
A15: 46002 | B15: 2 | C15: ef1a:2xLynk:tdmSG(J) (F1 of allele 302) | D15: tdmScarlet3S2:H2B-tol2 (F1 of allele 324) | G15: None | H15: None | I15: 45999 | J15: 0.41666667 | K15: LHDH | M15: 46002 | Q15: muscle, notochord, spinal_cord, skin, tail, blood vessel | T15: X:\abcabc\Aang_Foundation\20251211_mem-histone | U15: 7148
A16: 46002 | B16: 3 | C16: casper | D16: (F1 of allele 361) | G16: None | H16: None | I16: 46001 | J16: 0.41666667 | K16: DH | M16: 46002 | T16: X:\abcabc\Exploratory_fish\20251211_microtubule
A17: 46001 | B17: 1 | C17: ef1a:2xLynk:tdmSG(J) (F1 of allele 302) | D17: tdmScarlet3S2:H2B-tol2 (F1 of allele 324) | G17: None | H17: None | I17: 45999 | J17: 0.41666667 | K17: DH | M17: 46001 | Q17: muscle, tail, notochord, spinal_cord, hindbrain, skin | T17: X:\abcabc\Aang_Foundation\20251210_mem-histone | U17: 5161
A18: 46001 | B18: 2 | C18: ef1a:2xLynk:tdmSG(J) (F1 of allele 302) | D18: tdmScarlet3S2:H2B-tol2 (F1 of allele 324) | G18: None | H18: None | I18: 45999 | J18: 0.41666667 | K18: DH | M18: 46001 | Q18: muscle, tail, notochord, spinal_cord, hindbrain, skin | T18: X:\abcabc\Korra_Foundation\20251210_mem-histone | U18: 6743
A19: 46000 | B19: 1 | C19: ef1a:2xLynk:tdmSG(J) (F1 of allele 301) | D19: tdmScarlet3S2:H2B-tol2 (F1 of allele 324) | G19: None | H19: None | I19: 45999 | J19: 0.41666667 | K19: DH | M19: 46000 | Q19: muscle, tail, notochord, spinal_cord, hindbrain, skin | T19: X:\abcabc\Aang_Foundation\20251209_mem-histone | U19: 7976
A20: 46000 | B20: 2 | C20: ef1a:2xLynk:tdmSG(J) (F1 of allele 301) | D20: tdmScarlet3S2:H2B-tol2 (F1 of allele 324) | G20: None | H20: None | I20: 45999 | J20: 0.41666667 | K20: DH | M20: 46000 | Q20: skin, muscle, tail, notochord, spinal_cord, hindbrain | T20: X:\abcabc\Korra_Foundation\20251209_mem-histone | U20: 3246
A21: 45999 | B21: 1 | C21: ef1a:2xLynk:tdmSG(J) (F1 of allele 301) | D21: tdmScarlet3S2:H2B-tol2 (F1 of allele 324) | G21: None | H21: None | I21: 45998 | J21: 0.41666667 | K21: VTUHD | M21: 45999 | Q21: brain, skin, muscle, tail | T21: X:\abcabc\Korra_Foundation\20251208_mem-histone | U21: 2591
A22: 45999 | B22: 2 | C22: ef1a:2xLynk:tdmSG(J) (F1 of allele 301) | D22: tdmScarlet3S2:H2B-tol2 (F1 of allele 324) | G22: None | H22: None | I22: 45998 | J22: 0.41666667 | K22: VTUHD | M22: 45999 | Q22: brain, skin, muscle, tail | T22: X:\abcabc\Aang_Foundation\20251208_mem | U22: 3482
A23: 45996 | B23: 1 | C23: ef1a:2xLynk:tdmSG(J) (F1 of allele 302) | D23: tdmScarlet3S2:H2B-tol2 (F1 of allele 324) | G23: None | H23: None | I23: 45992 | J23: 0.41666667 | K23: LHDH | M23: 45996 | T23: X:\abcabc\Korra_Foundation\20241205_mem-histone
A24: 45996 | B24: 2 | C24: ef1a:2xLynk:tdmSG(J) (F1 of allele 302) | D24: tdmScarlet3S2:H2B-tol2 (F1 of allele 324) | G24: None | H24: None | I24: 45992 | J24: 0.41666667 | K24: LHDH | M24: 45996 | T24: X:\abcabc\Aang_Foundation\20251205_mem-histone
A25: 45995 | B25: 1 | C25: Tg(pDQM155)346 ef1a-extended:DHB:tdmSG-tol2 (cell cycle indicator) (F1 of allele 346) | D25: memrane tdmScarlet3S2 (F1 of allele 325) | F25: mScarlet3-S2:H2B | G25: None | H25: None | I25: 45994 | J25: 0.41666667 | K25: DH | M25: 45995 | T25: X:\abcabc\Aang_Foundation\20251204_cdk_sensor_red_mem_red_nuc
A26: 45995 | B26: 2 | C26: tdmScarlet3S2:H2B-tol2 (F1 of allele 324) | D26: ef1a:2xLynk:tdmSG(J) (F1 of allele 302) | G26: None | H26: None | I26: 45992 | J26: 0.41666667 | K26: DH | M26: 45995 | T26: X:\abcabc\Korra_Foundation\20251204_mem_histone
A27: 45994 | B27: 1 | C27: casper | D27: memrane tdmScarlet3S2 (F1 of allele 325) | E27: pDQM141(ef1a:linker:mGold2t:linker-attB (tol2)) | G27: None | H27: None | I27: 45992 | J27: 0.41666667 | K27: DH | M27: 45994 | Q27: skin, muscle, tail, neuromast, notochord, spinal_cord, hindbrain | T27: X:\abcabc\Aang_Foundation\20251203_mem-cytosolic | U27: 8100
A28: 45994 | B28: 2 | C28: casper | D28: memrane tdmScarlet3S2 (F1 of allele 325) | E28: pDQM141(ef1a:linker:mGold2t:linker-attB (tol2)) | G28: None | H28: None | I28: 45992 | J28: 0.41666667 | K28: DH | M28: 45994 | Q28: skin, muscle, tail, neuromast, notochord, spinal_cord, hindbrain | T28: X:\abcabc\Korra_Foundation\20251203_mem-cytosolic | U28: 7393
A29: 45993 | B29: 1 | C29: casper | D29: memrane tdmScarlet3S2 (F1 of allele 325) | E29: pDQM141(ef1a:linker:mGold2t:linker-attB (tol2)) | G29: None | H29: None | I29: 45992 | J29: 0.45833333 | K29: DH | M29: 45993 | Q29: brain, skin, ear | T29: X:\abcabc\Korra_Foundation\20251202_mem-cytosolic | U29: 5960
A30: 45993 | B30: 2 | C30: casper | D30: memrane tdmScarlet3S2 (F1 of allele 325) | E30: pDQM141(ef1a:linker:mGold2t:linker-attB (tol2)) | G30: None | H30: None | I30: 45992 | J30: 0.45833333 | K30: DH | M30: 45993 | Q30: brain, skin, ear | T30: X:\abcabc\Aang_Foundation\20251202_mem-cytosolic | U30: 5100
A31: 45989 | B31: 1 | C31: ef1a:2xLynk:tdmSG(J) (F1 of allele 302) | D31: tdmScarlet3S2:H2B-tol2 (F1 of allele 324) | G31: None | H31: None | I31: 45987 | J31: 0.45833333 | K31: DH | M31: 45989 | Q31: skin, muscle, tail, neuromast, notochord, spinal_cord, hindbrain | T31: X:\abcabc\Aang_Foundation\20251128_mem-histone | U31: 6461
A32: 45989 | B32: 2 | C32: ef1a:2xLynk:tdmSG(J) (F1 of allele 302) | D32: tdmScarlet3S2:H2B-tol2 (F1 of allele 324) | G32: None | H32: None | I32: 45987 | J32: 0.45833333 | K32: DH | M32: 45989 | Q32: skin, muscle, tail, neuromast, notochord, blood vessel, spinal_cord | T32: X:\abcabc\Korra_Foundation\20251128_mem-histone | U32: 5867
A33: 45987 | B33: 1 | C33: ef1a:2xLynk:tdmSG(J) (F1 of allele 301) | D33: tdmScarlet3S2:H2B-tol2 (F1 of allele 324) | G33: None | H33: None | I33: 45982 | J33: 0.45833333 | K33: LHUH | M33: 45987 | Q33: skin, muscle, tail, neuromast, notochord, blood vessel, spinal_cord, hindbrain | T33: X:\abcabc\Aang_Foundation\20251126_mem-histone | U33: 5990
A34: 45987 | B34: 2 | C34: ef1a:2xLynk:tdmSG(J) (F1 of allele 301) | D34: tdmScarlet3S2:H2B-tol2 (F1 of allele 324) | G34: None | H34: None | I34: 45982 | J34: 0.45833333 | K34: LHUH | M34: 45987 | Q34: skin, muscle, tail, neuromast, notochord, blood vessel, spinal_cord, hindbrain | T34: X:\abcabc\Korra_Foundation\20251126_mem-histone | U34: 11572
A35: 45986 | B35: 1 | C35: ef1a:2xLynk:tdmSG(J) (F1 of allele 301) | D35: tdmScarlet3S2:H2B-tol2 (F1 of allele 324) | G35: None | H35: None | I35: 45982 | J35: 0.45833333 | K35: LHUH | M35: 45986 | Q35: skin, muscle, tail, neuromast, notochord, blood vessel, spinal_cord | T35: X:\abcabc\Aang_Foundation\20251125_mem-histone | U35: 3072
A36: 45986 | B36: 2 | C36: ef1a:2xLynk:tdmSG(J) (F1 of allele 301) | D36: tdmScarlet3S2:H2B-tol2 (F1 of allele 324) | G36: None | H36: None | I36: 45982 | J36: 0.45833333 | K36: LHUH | M36: 45986 | Q36: skin, muscle, tail, neuromast, notochord, blood vessel, spinal_cord | T36: X:\abcabc\Korra_Foundation\20251125_mem-histone | U36: 4372
A37: 45985 | B37: 1 | C37: ef1a:2xLynk:tdmSG(J) (F1 of allele 301) | D37: tdmScarlet3S2:H2B-tol2 (F1 of allele 324) | G37: None | H37: None | I37: 45982 | J37: 0.45833333 | K37: LHUH | M37: 45985 | Q37: skin, muscle, tail, neuromast, notochord, blood vessel | T37: X:\abcabc\Aang_Foundation\20251124_mem-histone | U37: 4515
A38: 45985 | B38: 2 | C38: ef1a:2xLynk:tdmSG(J) (F1 of allele 301) | D38: tdmScarlet3S2:H2B-tol2 (F1 of allele 324) | G38: None | H38: None | I38: 45982 | J38: 0.45833333 | K38: LHUH | M38: 45985 | Q38: skin, muscle, tail, neuromast, notochord, blood vessel | T38: X:\abcabc\Korra_Foundation\20251124_mem-histone | U38: 7895
A39: 45982 | B39: 2 | C39: ef1a:2xLynk:tdmSG(J) (F1 of allele 301) | D39: tdmScarlet3S2:H2B-tol2 (F1 of allele 324) | G39: None | H39: None | I39: 45980 | J39: 0.45833333 | K39: DH | M39: 45982 | Q39: skin, spinal_cord, hindbrain, brain, muscle, tail, neuromast | T39: X:\abcabc\Korra_Foundation\20251121_mem-histone | U39: 8417
A40: 45978 | B40: 2 | C40: ef1a:2xLynk:tdmSG(J) (F1 of allele 302) | D40: tdmScarlet3S2:H2B-tol2 (F1 of allele 324) | G40: None | H40: None | I40: 45976 | J40: 0.45833333 | K40: DH | M40: 45978 | Q40: skin, spinal_cord, hindbrain, brain, muscle | T40: X:\abcabc\Korra_Foundation\20251117_mem-histone | U40: 2600
...

Sheet Weekly ZF Imaging Plan
B1: Age (hpf) | C1: Transgene / labels (mRNA/plasmid/etc) | D1: Comments
A2: Monday | B2: 72 | C2: mSG-mem x Skittles mTFP1/mChilada/miRFP670-2 | D2: test construct and comment about bleaching, abundance
A3: Tuesday | B3: 24 | C3: mSG-mem x H2B (mChilada and mYH available) | D3: which is better? mYH or mChilada
A4: Wed | B4: 48 | C4: mSG-mem x H2B (mChilada and mYH available)
A5: Thursday | B5: 24 | C5: mSG-mem x mChilada:H2B
A6: Friday | B6: 48 | C6: mSG-mem x mChilada:H2B
A8: Feb 10-14
A9: Monday | B9: 72hpf | C9: mSG-mem x mYH:H2B | D9: allele 308, ox rnf/csp on 2/7/25
A10: Tuesday | B10: 24hpf | C10: mSG-mem x mChilada:H2B | D10: allele 301 (F2s ox to csp/rnf on 2/10/25)
A11: Wed | B11: 48hpf | C11: mSG-mem x mChilada:H2B or mYH:H2B | D11: allele 301 (F2s ox to csp/rnf on 2/10/25)
A12: Thursday | B12: 24hpf or 72hpf | C12: mSG-mem x mYH:H2B | D12: allele 301 (F2s ox to csp/rnf on 2/10/25)
A13: Friday | B13: 48hpf | C13: mSG-mem x mYH:H2B
A15: Feb 17-21
A17: Tuesday | B17: 24 hpf | C17: mSG-mem x h2b:Halo | D17: allele 301 ox to ef1a:H2B:Halo on 2/17/25
A18: Wed | B18: 48hpf | C18: mSG-mem x h2b:Halo | D18: allele 301 ox to ef1a:H2B:Halo on 2/17/25
A19: Thursday | B19: 24 hpf | C19: 5FP skittles x mSG-mem | D19: allele 309 (cryaa/skittles 5FP) x allele 301 (mem:SG) on 2/19/25
A20: Friday | B20: 48 hpf | C20: 5FP skittles x mSG-mem | D20: allele 309 (cryaa/skittles 5FP) x allele 301 (mem:SG) on 2/19/25
A22: Feb 24-28
A24: Tuesday | B24: 24 hpf | C24: mSG-mem x mYH:H2B | D24: allele 301 F2 ox to rnf
A25: Wed | B25: 48 hpf | C25: mSG-mem x mYH:H2B | D25: allele 301 F2 ox to rnf
A26: Thursday | B26: 72 hpf / 24hpf | C26: mSG-mem x mYH:H2B | D26: allele 301 F2 ox to rnf, allele 301 F1 ox to rnf
A27: Friday | B27: 48 hpf | C27: mSG-mem x mYH:H2B | D27: allele 301 F1 ox to rnf
A29: March 3-7
A30: Monday | B30: 72hpf | C30: mSG-mem x mYH:H2B | D30: allele 301 F2 ox to rnf
A31: Tuesday | B31: 24 hpf | C31: mSG-mem x mYH:H2B | D31: allele 301 F2 ix
A32: Wed | B32: 48 hpf | C32: mSG-mem x mYH:H2B | D32: allele 301 F2 ix
A33: Thursday | B33: 72 hpf | C33: skittles 5FP + mem:mSG mRNA | D33: allele 309 ox to rnf
A34: Friday | B34: 24 hpf | C34: mSG-mem x mScarlet3-S2:H2B | D34: allele 301 F2 ox to rnf
A36: March 10-14
A37: Monday | B37: 0 hpf | C37: mSG-mem | D37: allele 301 F2 ix
A38: Tuesday | B38: 24 hpf | C38: ef1a:mTFP1 + ef1a:mBeRFP | D38: allele 301 F2 ix (or ox to rnf)
A39: Wed | B39: 48 hpf | C39: mSg-mem x mScarlet3-S2:H2B | D39: allele 301 F2 ix
A40: Thursday | B40: 24 hpf | C40: skittles 5FP x mSG-mem | D40: allele 309 male x allele 301 F2 female + phiC mRNA
A41: Friday | B41: 24 hpf | C41: mSg-mem x mScarlet3-S2:H2B (or skittles?) | D41: allele 301 F1 ox to rnf
A43: March 17-21
A44: Monday | B44: 72 hpf | C44: mSg-mem x mScarlet3-S2:H2B | D44: allele 301 F2 male ox to rnf
A45: Tuesday | B45: 24 hpf | C45: mSg-mem x mScarlet3-S2:H2B | D45: allele 301 F2 female ox to rnf
A46: Wed | B46: 48 hpf | C46: mSg-mem x mScarlet3-S2:H2B | D46: allele 301 F2 female ox to rnf
A47: Thursday | B47: 72 hpf | C47: mSg-mem x mScarlet3-S2:H2B (or 24hpf skittles) | D47: allele 301 F2 female ox to rnf, skittles = allele 313 F1 male ox to rnf female
A48: Friday | B48: 24 hpf | C48: mSg-mem x mScarlet3-S2:H2B (or 48hpf skittles)
...

Sheet Visual imaging schedule
B1: DAILY SCHEDULE
B2: Week of: | C2: 45999
A3: Strains of fish | C3: 45999 | D3: =C2+1 -> 46000 | E3: =C2+2 -> 46001 | F3: =C2+3 -> 46002 | G3: =C2+4 -> 46003 | H3: =C2+5 -> 46004 | I3: =C2+6 -> 46005
C4: =UPPER(TEXT(C3, "DDDD")) -> MONDAY | D4: =UPPER(TEXT(D3, "DDDD")) -> TUESDAY | E4: =UPPER(TEXT(E3, "DDDD")) -> WEDNESDAY | F4: =UPPER(TEXT(F3, "DDDD")) -> THURSDAY | G4: =UPPER(TEXT(G3, "DDDD")) -> FRIDAY | H4: =UPPER(TEXT(H3, "DDDD")) -> SATURDAY | I4: =UPPER(TEXT(I3, "DDDD")) -> SUNDAY
A6: mChilada | B6: 24 hpf | C6: mem:SG + H2B:mScarlet3S2 | D6: mem:SG + H2B:mScarlet3S2 | E6: mem:SG + H2B:mScarlet3S2 | F6: mem:SG + H2B:mScarlet3S2 | G6: mem:SG + H2B:mScarlet3S2
A7: mScarlet3S2 | B7: 48 hpf
A8: memHalo | B8: 72 hpf | F8: mSG microtubules
B9: 96 hpf
B28: NOTES | G28: TO DO

Sheet Dev Timescales
A1: Stage & Time (hpf) | B1: Key External / Morphological Changes | C1: Notochord | D1: Somite / Muscle | E1: CNS (Brain & Spinal Cord) | F1: Brain ventricles/ Chloro plexus | G1: Eye Development | H1: Ear (Otic) Dev. | I1: Nasal Pits | J1: Heart & Circulation | K1: Tail Development
A2: Zygote Period (0 – 0.75 hpf) | B2: - Single-cell zygote - Fertilization and cleavage initiation
A3: Imaging interval, priority (low/med/high) | B3: 1 min / low
A4: Cleavage Period (0.75 – 2.25 hpf) | B4: - Rapid synchronous cell divisions (2-, 4-, 8-cell, etc.) - Minimal cytoplasmic growth | C4: - Still notochord progenitors within axial mesoderm
A5: Imaging interval, priority (low/med/high) | B5: 1 min / low | C5: 1 min / low
A7: Blastula Period (2.25 – 5.25 hpf) | B7: - Formation of blastoderm (1000+ cells) - Dome stage, yolk syncytial layer forms | C7: - Axial mesoderm cells are located centrally but not morphologically distinct | E7: - Neural fate begins to be specified among blastoderm cells | G7: - Eye field specification still minimal | J7: - Cardiogenic mesoderm specified at lateral positions
A8: Imaging interval, priority (low/med/high) | B8: 1 min / low
A9: Gastrula Period (5.25 – 10.33 hpf) | B9: - Epiboly: blastoderm cells move down over the yolk - Germ layers (ectoderm, mesoderm, endoderm) established - Body axes set | C9: - Notochord precursors in the axial mesoderm begin to converge and elongate | D9: - Paraxial mesoderm (future somites) laid out alongside notochord region | E9: - Neural plate begins to form anteriorly (~10 hpf); future brain/spinal cord territories become regionally distinct | G9: - Early positioning of prospective eye fields in anterior neural plate | H9: - Prospective otic territory in the anterior-lateral ectoderm (not yet morphologically visible) | J9: - Cardiac precursors in lateral plate mesoderm (heart field) | K9: - Tail bud emerges at the posterior end of the embryo (late gastrula)
A10: Imaging interval, priority (low/med/high) | E10: 1 min / med | G10: 30 s / low | H10: 30 s / low | K10: 30 s / low
A11: Segmentation Period (10.33 – 24 hpf) | B11: - Somitogenesis (formation of somite 'blocks') - Morphological elongation of the embryo - Axis curvature becomes evident | C11: - Notochord cells arrange into a distinct rod; by ~14 hpf, notochord is visible along midline | D11: - Somites begin forming sequentially from anterior to posterior (~10–20 hpf); up to ~30 somites by 24 hpf | E11: - Neural plate → Neural keel → Neural rod (~10–18 hpf); primary brain vesicles (fore/mid/hindbrain) visible by ~24 hpf | G11: - Optic vesicles start to evaginate from the forebrain region (~16–18 hpf); lens placode thickens (~24 hpf) | H11: - Otic placode appears (~18–20 hpf); beginning of otic vesicle formation | J11: - Heart tube forms and initiates heartbeat (~22–24 hpf); early circulation may start near the end of this period (24–26 hpf) | K11: - Tail elongates as additional somites form; posterior extension of notochord and neural tube
A12: Imaging interval, priority (low/med/high) | E12: 1 min / med | G12: 30 s / low | H12: 30 s / low | K12: 30 s / low
A13: Pharyngula Period (24 – 48 hpf) | B13: - Pharyngeal arches visible - Pronounced head morphogenesis - Pigment cells appear (initial melanophores) | C13: - Notochord becomes more rigid; influences neural tube patterning | D13: - Somites become more defined and begin to develop muscle fibers (myotomes) | E13: - Brain subdivided into fore/mid/hindbrain domains; spinal cord canal forms (central lumen) | G13: - Retinal pigment first visible (~24–36 hpf); lens differentiates; eye size increases | H13: - Otic vesicle closes to form fluid-filled structure (~24–36 hpf); hair cells begin differentiating | J13: - Heart tube loops; chamber demarcation more evident (~36–48 hpf); circulation fully established; RBCs flow through body | K13: - Tail finfold becomes more distinct; tail continues to lengthen
A14: Imaging interval, priority (low/med/high) | E14: 1 min / med | G14: 30 s / high | H14: 30 s / high | K14: 30 s / high
A15: Hatching Period (48 – 72 hpf) | B15: - Larvae often break out of the chorion (using hatching gland enzymes) - Increased pigment - Start of free-swimming | C15: - Notochord straightens further; structural support for the developing spinal column | D15: - Visible trunk muscles with defined chevron-shaped somites | E15: - Ongoing brain growth; major brain subdivisions (telencephalon, diencephalon, mesencephalon, rhombencephalon) recognized; spinal cord matures | G15: - Eye well pigmented; retina layering increases in complexity | H15: - Otic vesicle matures; more hair cells differentiate; beginning of vestibular function | J15: - Heart loops fully and becomes more robust; stronger, coordinated blood flow; further vessel branching | K15: - Tail fully extended; early finfold structures more evident; some fin rays begin to show initial condensations
A16: Imaging interval, priority (low/med/high) | E16: 1 min / med | G16: 30 s / high | H16: 30 s / high | K16: 30 s / high
A17: Early Larval Period (72 hpf – 6 dpf) | B17: - Swim bladder inflation (around 4–5 dpf) - Mouth/jaw morphogenesis allows first feeding (~5 dpf) - Rapid growth and pigmentation | C17: - Notochord remains as core 'spinal rod,' later to be replaced by vertebral column elements | D17: - Myotomes enlarge; muscle fiber differentiation continues; pectoral fin buds more prominent | E17: - Further refinement of neural circuits; increased motor coordination; larvae become more responsive to stimuli | G17: - Retinal layering refines; cones develop; visually guided behavior emerges; eye size increases | H17: - Internal ear (otic capsule) continues to form semicircular canals; improved hearing/balance | J17: - Heart chambers (atrium, ventricle) clearly distinct by ~3–4 dpf; definitive hematopoiesis ramps up in kidney and thymus | K17: - Ongoing elongation; fin development (pectoral fins, beginnings of dorsal/anal fins) is more pronounced; tail fin extends further
A18: Imaging interval, priority (low/med/high) | E18: 1 min / low | G18: 30 s / high | H18: 30 s / high | K18: 30 s / high

Sheet Orientations
A1: LHDH | B1: Lateral, Heart Down, Head front | E1: These were described in this presentation: | F1: fish orientation.pptx
A2: LHUH | B2: Lateral, Heart Up, Head front
A3: LHUT | B3: Lateral, Heart Up, Tail front
A4: LHDT | B4: Lateral, Heart Down, Tail front
A5: VTUHD | B5: Vertical, Tail Up, Heart at DO
A6: VTUHE | B6: Vertical, Tail Up, Heart at EO
A7: VHUHD | B7: Vertical, Head Up, Heart at DO
A8: VHUHE | B8: Vertical, Head Up, Heart at EO
A9: DH | B9: Dorsal, Head user
A10: DT | B10: Dorsal, Tail user
A11: VT | B11: Ventral, Tail user
A12: VH | B12: Ventral, Head user
A13: LHR | B13: Lateral, Head pointing to the right, from the mounter's perspective

Sheet DM_fish
A1: Unique (gather from: col 'B' of 'external_fish' sheet, column 'B' here) | B1: Unique targets (build array out of targets, then find unique values, filter away blanks, if error leave this blank) | C1: Plasmid F Allele String | D1: F Allele String | E1: F | F1: =IFERROR(__xludf.DUMMYFUNCTION("IMPORTRANGE(""https://docs.google.com/spreadsheets/d/1458f4-GkyML2z-1bvHCzaFbD7yQ8l37XUJsO63XH9oo/edit"",""fish!A:S"")"),"p") -> p | G1: =IFERROR(__xludf.DUMMYFUNCTION("""COMPUTED_VALUE"""),"Plasmid description") -> Plasmid description | H1: =IFERROR(__xludf.DUMMYFUNCTION("""COMPUTED_VALUE"""),"DOB") -> DOB | I1: =IFERROR(__xludf.DUMMYFUNCTION("""COMPUTED_VALUE"""),"Plasmid") -> Plasmid | J1: =IFERROR(__xludf.DUMMYFUNCTION("""COMPUTED_VALUE"""),"Transgenesis") -> Transgenesis | K1: =IFERROR(__xludf.DUMMYFUNCTION("""COMPUTED_VALUE"""),"Allele") -> Allele | L1: =IFERROR(__xludf.DUMMYFUNCTION("""COMPUTED_VALUE"""),"genetic background") -> genetic background | M1: =IFERROR(__xludf.DUMMYFUNCTION("""COMPUTED_VALUE"""),"Screening Date") -> Screening Date | N1: =IFERROR(__xludf.DUMMYFUNCTION("""COMPUTED_VALUE"""),"mom") -> mom | O1: =IFERROR(__xludf.DUMMYFUNCTION("""COMPUTED_VALUE"""),"dad") -> dad | P1: =IFERROR(__xludf.DUMMYFUNCTION("""COMPUTED_VALUE"""),"line_building_stage") -> line_building_stage | Q1: =IFERROR(__xludf.DUMMYFUNCTION("""COMPUTED_VALUE"""),"Notes") -> Notes | R1: =IFERROR(__xludf.DUMMYFUNCTION("""COMPUTED_VALUE"""),"target 1") -> target 1 | S1: =IFERROR(__xludf.DUMMYFUNCTION("""COMPUTED_VALUE"""),"excitation wavelength 1") -> excitation wavelength 1 | T1: =IFERROR(__xludf.DUMMYFUNCTION("""COMPUTED_VALUE"""),"target 2") -> target 2 | U1: =IFERROR(__xludf.DUMMYFUNCTION("""COMPUTED_VALUE"""),"excitation wavelength 2") -> excitation wavelength 2 | V1: =IFERROR(__xludf.DUMMYFUNCTION("""COMPUTED_VALUE"""),"target 3") -> target 3 | W1: =IFERROR(__xludf.DUMMYFUNCTION("""COMPUTED_VALUE"""),"excitation wavelength 3") -> excitation wavelength 3 | X1: =IFERROR(__xludf.DUMMYFUNCTION("""COMPUTED_VALUE"""),"target 4") -> target 4
A2: casper | B2: =IFERROR(__xludf.DUMMYFUNCTION("IFERROR(JOIN("","", UNIQUE(filter({VLOOKUP(A2,external_fish!C:X,13, FALSE); VLOOKUP(A2,external_fish!C:X,15, FALSE); VLOOKUP(A2,external_fish!C:X,17, FALSE); VLOOKUP(A2,external_fish!C:X,19, FALSE)}, {VLOOKUP(A2,external_fish!C:X,13, FALSE); VLOOKUP(A2,ex"&"ternal_fish!C:X,15, FALSE); VLOOKUP(A2,external_fish!C:X,17, FALSE); VLOOKUP(A2,external_fish!C:X,19, FALSE)}<>""""))), """")"),"") | C2: =IF(ISBLANK(D2), F2, CONCATENATE(G2, " (", E2, " of allele ", K2, ")" )) -> ef1a:2xLynk:tdmSG(J) (F1 of allele 301) | D2: =IF(ISBLANK(K2), , CONCATENATE("(", E2, " of allele ", K2, ")")) -> (F1 of allele 301) | E2: =IFERROR(__xludf.DUMMYFUNCTION("IFERROR(REGEXEXTRACT(N2, ""F\d+""), ""F1"")"),"F1") -> F1 | F2: =IFERROR(__xludf.DUMMYFUNCTION("""COMPUTED_VALUE"""),"tandem mem:mStayGold") -> tandem mem:mStayGold | G2: =IFERROR(__xludf.DUMMYFUNCTION("""COMPUTED_VALUE"""),"ef1a:2xLynk:tdmSG(J)") -> ef1a:2xLynk:tdmSG(J) | H2: =IFERROR(__xludf.DUMMYFUNCTION("""COMPUTED_VALUE"""),45520) -> 45520 | I2: =IFERROR(__xludf.DUMMYFUNCTION("""COMPUTED_VALUE"""),"pDQM005") -> pDQM005 | J2: =IFERROR(__xludf.DUMMYFUNCTION("""COMPUTED_VALUE"""),"tol2") -> tol2 | K2: =IFERROR(__xludf.DUMMYFUNCTION("""COMPUTED_VALUE"""),301) -> 301 | L2: =IFERROR(__xludf.DUMMYFUNCTION("""COMPUTED_VALUE"""),"casper") -> casper | M2: =IFERROR(__xludf.DUMMYFUNCTION("""COMPUTED_VALUE"""),45610) -> 45610 | N2: =IFERROR(__xludf.DUMMYFUNCTION("""COMPUTED_VALUE"""),"csp") -> csp | O2: =IFERROR(__xludf.DUMMYFUNCTION("""COMPUTED_VALUE"""),"csp") -> csp | P2: =IFERROR(__xludf.DUMMYFUNCTION("""COMPUTED_VALUE"""),"P0_founder") -> P0_founder | Q2: =IFERROR(__xludf.DUMMYFUNCTION("""COMPUTED_VALUE"""),"male #8 - best founder (40-50% transmission, multiple alleles, bright!!!)") -> male #8 - best founder (40-50% transmission, multiple alleles, bright!!!) | R2: =IFERROR(__xludf.DUMMYFUNCTION("""COMPUTED_VALUE"""),"membrane") -> membrane | S2: =IFERROR(__xludf.DUMMYFUNCTION("""COMPUTED_VALUE"""),488) -> 488
A3: ef1a:2xLynk:tdm:Halo | B3: =IFERROR(__xludf.DUMMYFUNCTION("IFERROR(JOIN("","", UNIQUE(filter({VLOOKUP(A3,external_fish!C:X,13, FALSE); VLOOKUP(A3,external_fish!C:X,15, FALSE); VLOOKUP(A3,external_fish!C:X,17, FALSE); VLOOKUP(A3,external_fish!C:X,19, FALSE)}, {VLOOKUP(A3,external_fish!C:X,13, FALSE); VLOOKUP(A3,ex"&"ternal_fish!C:X,15, FALSE); VLOOKUP(A3,external_fish!C:X,17, FALSE); VLOOKUP(A3,external_fish!C:X,19, FALSE)}<>""""))), """")"),"membrane") -> membrane | C3: =IF(ISBLANK(D3), F3, CONCATENATE(G3, " (", E3, " of allele ", K3, ")" )) -> ef1a:2xLynk:tdmSG(J) (F1 of allele 301) | D3: =IF(ISBLANK(K3), , CONCATENATE("(", E3, " of allele ", K3, ")")) -> (F1 of allele 301) | E3: =IFERROR(__xludf.DUMMYFUNCTION("IFERROR(REGEXEXTRACT(N3, ""F\d+""), ""F1"")"),"F1") -> F1 | F3: =IFERROR(__xludf.DUMMYFUNCTION("""COMPUTED_VALUE"""),"tandem mem:mStayGold") -> tandem mem:mStayGold | G3: =IFERROR(__xludf.DUMMYFUNCTION("""COMPUTED_VALUE"""),"ef1a:2xLynk:tdmSG(J)") -> ef1a:2xLynk:tdmSG(J) | H3: =IFERROR(__xludf.DUMMYFUNCTION("""COMPUTED_VALUE"""),45608) -> 45608 | I3: =IFERROR(__xludf.DUMMYFUNCTION("""COMPUTED_VALUE"""),"pDQM005") -> pDQM005 | J3: =IFERROR(__xludf.DUMMYFUNCTION("""COMPUTED_VALUE"""),"tol2") -> tol2 | K3: =IFERROR(__xludf.DUMMYFUNCTION("""COMPUTED_VALUE"""),301) -> 301 | L3: =IFERROR(__xludf.DUMMYFUNCTION("""COMPUTED_VALUE"""),"casper") -> casper | M3: =IFERROR(__xludf.DUMMYFUNCTION("""COMPUTED_VALUE"""),45698) -> 45698 | N3: =IFERROR(__xludf.DUMMYFUNCTION("""COMPUTED_VALUE"""),"csp") -> csp | O3: =IFERROR(__xludf.DUMMYFUNCTION("""COMPUTED_VALUE"""),301) -> 301 | P3: =IFERROR(__xludf.DUMMYFUNCTION("""COMPUTED_VALUE"""),"F1_ox") -> F1_ox | Q3: =IFERROR(__xludf.DUMMYFUNCTION("""COMPUTED_VALUE"""),"F1s of male #8 - 3 tanks started with 1 tank = ++ 2 tanks = +++") -> F1s of male #8 - 3 tanks started with 1 tank = ++ 2 tanks = +++ | R3: =IFERROR(__xludf.DUMMYFUNCTION("""COMPUTED_VALUE"""),"membrane") -> membrane | S3: =IFERROR(__xludf.DUMMYFUNCTION("""COMPUTED_VALUE"""),488) -> 488
A4: from Swinburne lab - tank ID 344 (F1 of allele 45385) | B4: =IFERROR(__xludf.DUMMYFUNCTION("IFERROR(JOIN("","", UNIQUE(filter({VLOOKUP(A4,external_fish!C:X,13, FALSE); VLOOKUP(A4,external_fish!C:X,15, FALSE); VLOOKUP(A4,external_fish!C:X,17, FALSE); VLOOKUP(A4,external_fish!C:X,19, FALSE)}, {VLOOKUP(A4,external_fish!C:X,13, FALSE); VLOOKUP(A4,ex"&"ternal_fish!C:X,15, FALSE); VLOOKUP(A4,external_fish!C:X,17, FALSE); VLOOKUP(A4,external_fish!C:X,19, FALSE)}<>""""))), """")"),"membrane") -> membrane | C4: =IF(ISBLANK(D4), F4, CONCATENATE(G4, " (", E4, " of allele ", K4, ")" )) -> ef1a:2xLynk:tdmSG(J) (F1 of allele 301) | D4: =IF(ISBLANK(K4), , CONCATENATE("(", E4, " of allele ", K4, ")")) -> (F1 of allele 301) | E4: =IFERROR(__xludf.DUMMYFUNCTION("IFERROR(REGEXEXTRACT(N4, ""F\d+""), ""F1"")"),"F1") -> F1 | F4: =IFERROR(__xludf.DUMMYFUNCTION("""COMPUTED_VALUE"""),"tandem mem:mStayGold") -> tandem mem:mStayGold | G4: =IFERROR(__xludf.DUMMYFUNCTION("""COMPUTED_VALUE"""),"ef1a:2xLynk:tdmSG(J)") -> ef1a:2xLynk:tdmSG(J) | H4: =IFERROR(__xludf.DUMMYFUNCTION("""COMPUTED_VALUE"""),45608) -> 45608 | I4: =IFERROR(__xludf.DUMMYFUNCTION("""COMPUTED_VALUE"""),"pDQM005") -> pDQM005 | J4: =IFERROR(__xludf.DUMMYFUNCTION("""COMPUTED_VALUE"""),"tol2") -> tol2 | K4: =IFERROR(__xludf.DUMMYFUNCTION("""COMPUTED_VALUE"""),301) -> 301 | L4: =IFERROR(__xludf.DUMMYFUNCTION("""COMPUTED_VALUE"""),"casper") -> casper | N4: =IFERROR(__xludf.DUMMYFUNCTION("""COMPUTED_VALUE"""),301) -> 301 | O4: =IFERROR(__xludf.DUMMYFUNCTION("""COMPUTED_VALUE"""),301) -> 301 | P4: =IFERROR(__xludf.DUMMYFUNCTION("""COMPUTED_VALUE"""),"F2_ix") -> F2_ix | Q4: =IFERROR(__xludf.DUMMYFUNCTION("""COMPUTED_VALUE"""),"F2s of allele 301 incross") -> F2s of allele 301 incross | R4: =IFERROR(__xludf.DUMMYFUNCTION("""COMPUTED_VALUE"""),"membrane") -> membrane | S4: =IFERROR(__xludf.DUMMYFUNCTION("""COMPUTED_VALUE"""),488) -> 488
B5: =IFERROR(__xludf.DUMMYFUNCTION("IFERROR(JOIN("","", UNIQUE(filter({VLOOKUP(A5,C:X,13, FALSE); VLOOKUP(A5,C:X,15, FALSE); VLOOKUP(A5,C:X,17, FALSE); VLOOKUP(A5,C:X,19, FALSE)}, {VLOOKUP(A5,C:X,13, FALSE); VLOOKUP(A5,C:X,15, FALSE); VLOOKUP(A5,C:X,17, FALSE); VLOOKUP(A5,C:X,19, FALSE)}<>"&"""""))), """")"),"") | C5: =IF(ISBLANK(D5), F5, CONCATENATE(G5, " (", E5, " of allele ", K5, ")" )) -> ef1a:2xLynk:tdmSG(J) (F1 of allele 302) | D5: =IF(ISBLANK(K5), , CONCATENATE("(", E5, " of allele ", K5, ")")) -> (F1 of allele 302) | E5: =IFERROR(__xludf.DUMMYFUNCTION("IFERROR(REGEXEXTRACT(N5, ""F\d+""), ""F1"")"),"F1") -> F1 | F5: =IFERROR(__xludf.DUMMYFUNCTION("""COMPUTED_VALUE"""),"tandem mem:mStayGold") -> tandem mem:mStayGold | G5: =IFERROR(__xludf.DUMMYFUNCTION("""COMPUTED_VALUE"""),"ef1a:2xLynk:tdmSG(J)") -> ef1a:2xLynk:tdmSG(J) | H5: =IFERROR(__xludf.DUMMYFUNCTION("""COMPUTED_VALUE"""),45520) -> 45520 | I5: =IFERROR(__xludf.DUMMYFUNCTION("""COMPUTED_VALUE"""),"pDQM005") -> pDQM005 | J5: =IFERROR(__xludf.DUMMYFUNCTION("""COMPUTED_VALUE"""),"tol2") -> tol2 | K5: =IFERROR(__xludf.DUMMYFUNCTION("""COMPUTED_VALUE"""),302) -> 302 | L5: =IFERROR(__xludf.DUMMYFUNCTION("""COMPUTED_VALUE"""),"casper") -> casper | M5: =IFERROR(__xludf.DUMMYFUNCTION("""COMPUTED_VALUE"""),45610) -> 45610 | N5: =IFERROR(__xludf.DUMMYFUNCTION("""COMPUTED_VALUE"""),"csp") -> csp | O5: =IFERROR(__xludf.DUMMYFUNCTION("""COMPUTED_VALUE"""),"csp") -> csp | P5: =IFERROR(__xludf.DUMMYFUNCTION("""COMPUTED_VALUE"""),"P0_founder") -> P0_founder | Q5: =IFERROR(__xludf.DUMMYFUNCTION("""COMPUTED_VALUE"""),"male #11 - bright, low frequency transmission (<10%)") -> male #11 - bright, low frequency transmission (<10%) | R5: =IFERROR(__xludf.DUMMYFUNCTION("""COMPUTED_VALUE"""),"membrane") -> membrane | S5: =IFERROR(__xludf.DUMMYFUNCTION("""COMPUTED_VALUE"""),488) -> 488
A6: ef1a:2xLynk:tdmSG(J) (F1 of allele 301) | B6: =IFERROR(__xludf.DUMMYFUNCTION("IFERROR(JOIN("","", UNIQUE(filter({VLOOKUP(A6,C:X,13, FALSE); VLOOKUP(A6,C:X,15, FALSE); VLOOKUP(A6,C:X,17, FALSE); VLOOKUP(A6,C:X,19, FALSE)}, {VLOOKUP(A6,C:X,13, FALSE); VLOOKUP(A6,C:X,15, FALSE); VLOOKUP(A6,C:X,17, FALSE); VLOOKUP(A6,C:X,19, FALSE)}<>"&"""""))), """")"),"csp,male #8 - best founder (40-50% transmission, multiple alleles, bright!!!),488") -> csp,male #8 - best founder (40-50% transmission, multiple alleles, bright!!!),488 | C6: =IF(ISBLANK(D6), F6, CONCATENATE(G6, " (", E6, " of allele ", K6, ")" )) -> ef1a:2xLynk:tdmSG(J) (F1 of allele 302) | D6: =IF(ISBLANK(K6), , CONCATENATE("(", E6, " of allele ", K6, ")")) -> (F1 of allele 302) | E6: =IFERROR(__xludf.DUMMYFUNCTION("IFERROR(REGEXEXTRACT(N6, ""F\d+""), ""F1"")"),"F1") -> F1 | F6: =IFERROR(__xludf.DUMMYFUNCTION("""COMPUTED_VALUE"""),"tandem mem:mStayGold") -> tandem mem:mStayGold | G6: =IFERROR(__xludf.DUMMYFUNCTION("""COMPUTED_VALUE"""),"ef1a:2xLynk:tdmSG(J)") -> ef1a:2xLynk:tdmSG(J) | H6: =IFERROR(__xludf.DUMMYFUNCTION("""COMPUTED_VALUE"""),45621) -> 45621 | I6: =IFERROR(__xludf.DUMMYFUNCTION("""COMPUTED_VALUE"""),"pDQM005") -> pDQM005 | J6: =IFERROR(__xludf.DUMMYFUNCTION("""COMPUTED_VALUE"""),"tol2") -> tol2 | K6: =IFERROR(__xludf.DUMMYFUNCTION("""COMPUTED_VALUE"""),302) -> 302 | L6: =IFERROR(__xludf.DUMMYFUNCTION("""COMPUTED_VALUE"""),"casper") -> casper | M6: =IFERROR(__xludf.DUMMYFUNCTION("""COMPUTED_VALUE"""),45711) -> 45711 | N6: =IFERROR(__xludf.DUMMYFUNCTION("""COMPUTED_VALUE"""),"csp") -> csp | O6: =IFERROR(__xludf.DUMMYFUNCTION("""COMPUTED_VALUE"""),302) -> 302 | P6: =IFERROR(__xludf.DUMMYFUNCTION("""COMPUTED_VALUE"""),"F1_ox") -> F1_ox | Q6: =IFERROR(__xludf.DUMMYFUNCTION("""COMPUTED_VALUE"""),"F1s of male #11 (1 tank few fish surviving)") -> F1s of male #11 (1 tank few fish surviving) | R6: =IFERROR(__xludf.DUMMYFUNCTION("""COMPUTED_VALUE"""),"membrane") -> membrane | S6: =IFERROR(__xludf.DUMMYFUNCTION("""COMPUTED_VALUE"""),488) -> 488
A7: ef1a:2xLynk:tdmSG(J) (F1 of allele 302) | B7: =IFERROR(__xludf.DUMMYFUNCTION("IFERROR(JOIN("","", UNIQUE(filter({VLOOKUP(A7,C:X,13, FALSE); VLOOKUP(A7,C:X,15, FALSE); VLOOKUP(A7,C:X,17, FALSE); VLOOKUP(A7,C:X,19, FALSE)}, {VLOOKUP(A7,C:X,13, FALSE); VLOOKUP(A7,C:X,15, FALSE); VLOOKUP(A7,C:X,17, FALSE); VLOOKUP(A7,C:X,19, FALSE)}<>"&"""""))), """")"),"csp,male #11 - bright, low frequency transmission (<10%),488") -> csp,male #11 - bright, low frequency transmission (<10%),488 | C7: =IF(ISBLANK(D7), F7, CONCATENATE(G7, " (", E7, " of allele ", K7, ")" )) -> ef1a:2xLynk:tdmSG(J) (F1 of allele 302) | D7: =IF(ISBLANK(K7), , CONCATENATE("(", E7, " of allele ", K7, ")")) -> (F1 of allele 302) | E7: =IFERROR(__xludf.DUMMYFUNCTION("IFERROR(REGEXEXTRACT(N7, ""F\d+""), ""F1"")"),"F1") -> F1 | F7: =IFERROR(__xludf.DUMMYFUNCTION("""COMPUTED_VALUE"""),"tandem mem:mStayGold") -> tandem mem:mStayGold | G7: =IFERROR(__xludf.DUMMYFUNCTION("""COMPUTED_VALUE"""),"ef1a:2xLynk:tdmSG(J)") -> ef1a:2xLynk:tdmSG(J) | H7: =IFERROR(__xludf.DUMMYFUNCTION("""COMPUTED_VALUE"""),45621) -> 45621 | I7: =IFERROR(__xludf.DUMMYFUNCTION("""COMPUTED_VALUE"""),"pDQM005") -> pDQM005 | J7: =IFERROR(__xludf.DUMMYFUNCTION("""COMPUTED_VALUE"""),"tol2") -> tol2 | K7: =IFERROR(__xludf.DUMMYFUNCTION("""COMPUTED_VALUE"""),302) -> 302 | L7: =IFERROR(__xludf.DUMMYFUNCTION("""COMPUTED_VALUE"""),"casper") -> casper | N7: =IFERROR(__xludf.DUMMYFUNCTION("""COMPUTED_VALUE"""),302) -> 302 | O7: =IFERROR(__xludf.DUMMYFUNCTION("""COMPUTED_VALUE"""),302) -> 302 | P7: =IFERROR(__xludf.DUMMYFUNCTION("""COMPUTED_VALUE"""),"F2_ix") -> F2_ix | Q7: =IFERROR(__xludf.DUMMYFUNCTION("""COMPUTED_VALUE"""),"F2s of allele 302 incross") -> F2s of allele 302 incross | R7: =IFERROR(__xludf.DUMMYFUNCTION("""COMPUTED_VALUE"""),"membrane") -> membrane | S7: =IFERROR(__xludf.DUMMYFUNCTION("""COMPUTED_VALUE"""),488) -> 488
A8: ef1a:2xLynk:tdmSG(J) (F1 of allele 303) | B8: =IFERROR(__xludf.DUMMYFUNCTION("IFERROR(JOIN("","", UNIQUE(filter({VLOOKUP(A8,C:X,13, FALSE); VLOOKUP(A8,C:X,15, FALSE); VLOOKUP(A8,C:X,17, FALSE); VLOOKUP(A8,C:X,19, FALSE)}, {VLOOKUP(A8,C:X,13, FALSE); VLOOKUP(A8,C:X,15, FALSE); VLOOKUP(A8,C:X,17, FALSE); VLOOKUP(A8,C:X,19, FALSE)}<>"&"""""))), """")"),"csp,male #17 - bright, low frequency transmission (<10%),488") -> csp,male #17 - bright, low frequency transmission (<10%),488 | C8: =IF(ISBLANK(D8), F8, CONCATENATE(G8, " (", E8, " of allele ", K8, ")" )) -> ef1a:2xLynk:tdmSG(J) (F1 of allele 303) | D8: =IF(ISBLANK(K8), , CONCATENATE("(", E8, " of allele ", K8, ")")) -> (F1 of allele 303) | E8: =IFERROR(__xludf.DUMMYFUNCTION("IFERROR(REGEXEXTRACT(N8, ""F\d+""), ""F1"")"),"F1") -> F1 | F8: =IFERROR(__xludf.DUMMYFUNCTION("""COMPUTED_VALUE"""),"tandem mem:mStayGold") -> tandem mem:mStayGold | G8: =IFERROR(__xludf.DUMMYFUNCTION("""COMPUTED_VALUE"""),"ef1a:2xLynk:tdmSG(J)") -> ef1a:2xLynk:tdmSG(J) | H8: =IFERROR(__xludf.DUMMYFUNCTION("""COMPUTED_VALUE"""),45520) -> 45520 | I8: =IFERROR(__xludf.DUMMYFUNCTION("""COMPUTED_VALUE"""),"pDQM005") -> pDQM005 | J8: =IFERROR(__xludf.DUMMYFUNCTION("""COMPUTED_VALUE"""),"tol2") -> tol2 | K8: =IFERROR(__xludf.DUMMYFUNCTION("""COMPUTED_VALUE"""),303) -> 303 | L8: =IFERROR(__xludf.DUMMYFUNCTION("""COMPUTED_VALUE"""),"casper") -> casper | M8: =IFERROR(__xludf.DUMMYFUNCTION("""COMPUTED_VALUE"""),45610) -> 45610 | N8: =IFERROR(__xludf.DUMMYFUNCTION("""COMPUTED_VALUE"""),"csp") -> csp | O8: =IFERROR(__xludf.DUMMYFUNCTION("""COMPUTED_VALUE"""),"csp") -> csp | P8: =IFERROR(__xludf.DUMMYFUNCTION("""COMPUTED_VALUE"""),"P0_founder") -> P0_founder | Q8: =IFERROR(__xludf.DUMMYFUNCTION("""COMPUTED_VALUE"""),"male #17 - bright, low frequency transmission (<10%)") -> male #17 - bright, low frequency transmission (<10%) | R8: =IFERROR(__xludf.DUMMYFUNCTION("""COMPUTED_VALUE"""),"membrane") -> membrane | S8: =IFERROR(__xludf.DUMMYFUNCTION("""COMPUTED_VALUE"""),488) -> 488
A9: ef1a:2xLynk:tdmSG(J) (F1 of allele 304) | B9: =IFERROR(__xludf.DUMMYFUNCTION("IFERROR(JOIN("","", UNIQUE(filter({VLOOKUP(A9,C:X,13, FALSE); VLOOKUP(A9,C:X,15, FALSE); VLOOKUP(A9,C:X,17, FALSE); VLOOKUP(A9,C:X,19, FALSE)}, {VLOOKUP(A9,C:X,13, FALSE); VLOOKUP(A9,C:X,15, FALSE); VLOOKUP(A9,C:X,17, FALSE); VLOOKUP(A9,C:X,19, FALSE)}<>"&"""""))), """")"),"csp,male #23 - bright, low frequency transmission (<10%),488") -> csp,male #23 - bright, low frequency transmission (<10%),488 | C9: =IF(ISBLANK(D9), F9, CONCATENATE(G9, " (", E9, " of allele ", K9, ")" )) -> ef1a:2xLynk:tdmSG(J) (F1 of allele 303) | D9: =IF(ISBLANK(K9), , CONCATENATE("(", E9, " of allele ", K9, ")")) -> (F1 of allele 303) | E9: =IFERROR(__xludf.DUMMYFUNCTION("IFERROR(REGEXEXTRACT(N9, ""F\d+""), ""F1"")"),"F1") -> F1 | F9: =IFERROR(__xludf.DUMMYFUNCTION("""COMPUTED_VALUE"""),"tandem mem:mStayGold") -> tandem mem:mStayGold | G9: =IFERROR(__xludf.DUMMYFUNCTION("""COMPUTED_VALUE"""),"ef1a:2xLynk:tdmSG(J)") -> ef1a:2xLynk:tdmSG(J) | H9: =IFERROR(__xludf.DUMMYFUNCTION("""COMPUTED_VALUE"""),45637) -> 45637 | I9: =IFERROR(__xludf.DUMMYFUNCTION("""COMPUTED_VALUE"""),"pDQM005") -> pDQM005 | J9: =IFERROR(__xludf.DUMMYFUNCTION("""COMPUTED_VALUE"""),"tol2") -> tol2 | K9: =IFERROR(__xludf.DUMMYFUNCTION("""COMPUTED_VALUE"""),303) -> 303 | L9: =IFERROR(__xludf.DUMMYFUNCTION("""COMPUTED_VALUE"""),"casper") -> casper | M9: =IFERROR(__xludf.DUMMYFUNCTION("""COMPUTED_VALUE"""),45727) -> 45727 | N9: =IFERROR(__xludf.DUMMYFUNCTION("""COMPUTED_VALUE"""),"csp") -> csp | O9: =IFERROR(__xludf.DUMMYFUNCTION("""COMPUTED_VALUE"""),303) -> 303 | P9: =IFERROR(__xludf.DUMMYFUNCTION("""COMPUTED_VALUE"""),"F1_ox") -> F1_ox | Q9: =IFERROR(__xludf.DUMMYFUNCTION("""COMPUTED_VALUE"""),"F1s of male #17 1 tank started") -> F1s of male #17 1 tank started | R9: =IFERROR(__xludf.DUMMYFUNCTION("""COMPUTED_VALUE"""),"membrane") -> membrane | S9: =IFERROR(__xludf.DUMMYFUNCTION("""COMPUTED_VALUE"""),488) -> 488
A10: ef1a:2xLynk:tdmSG(J) (F1 of allele 305) | B10: =IFERROR(__xludf.DUMMYFUNCTION("IFERROR(JOIN("","", UNIQUE(filter({VLOOKUP(A10,C:X,13, FALSE); VLOOKUP(A10,C:X,15, FALSE); VLOOKUP(A10,C:X,17, FALSE); VLOOKUP(A10,C:X,19, FALSE)}, {VLOOKUP(A10,C:X,13, FALSE); VLOOKUP(A10,C:X,15, FALSE); VLOOKUP(A10,C:X,17, FALSE); VLOOKUP(A10,C:X,19, FA"&"LSE)}<>""""))), """")"),"csp,male #26 - bright, low frequency transmission (<10%),488") -> csp,male #26 - bright, low frequency transmission (<10%),488 | C10: =IF(ISBLANK(D10), F10, CONCATENATE(G10, " (", E10, " of allele ", K10, ")" )) -> ef1a:2xLynk:tdmSG(J) (F1 of allele 304) | D10: =IF(ISBLANK(K10), , CONCATENATE("(", E10, " of allele ", K10, ")")) -> (F1 of allele 304) | E10: =IFERROR(__xludf.DUMMYFUNCTION("IFERROR(REGEXEXTRACT(N10, ""F\d+""), ""F1"")"),"F1") -> F1 | F10: =IFERROR(__xludf.DUMMYFUNCTION("""COMPUTED_VALUE"""),"tandem mem:mStayGold") -> tandem mem:mStayGold | G10: =IFERROR(__xludf.DUMMYFUNCTION("""COMPUTED_VALUE"""),"ef1a:2xLynk:tdmSG(J)") -> ef1a:2xLynk:tdmSG(J) | H10: =IFERROR(__xludf.DUMMYFUNCTION("""COMPUTED_VALUE"""),45520) -> 45520 | I10: =IFERROR(__xludf.DUMMYFUNCTION("""COMPUTED_VALUE"""),"pDQM005") -> pDQM005 | J10: =IFERROR(__xludf.DUMMYFUNCTION("""COMPUTED_VALUE"""),"tol2") -> tol2 | K10: =IFERROR(__xludf.DUMMYFUNCTION("""COMPUTED_VALUE"""),304) -> 304 | L10: =IFERROR(__xludf.DUMMYFUNCTION("""COMPUTED_VALUE"""),"casper") -> casper | M10: =IFERROR(__xludf.DUMMYFUNCTION("""COMPUTED_VALUE"""),45610) -> 45610 | N10: =IFERROR(__xludf.DUMMYFUNCTION("""COMPUTED_VALUE"""),"csp") -> csp | O10: =IFERROR(__xludf.DUMMYFUNCTION("""COMPUTED_VALUE"""),"csp") -> csp | P10: =IFERROR(__xludf.DUMMYFUNCTION("""COMPUTED_VALUE"""),"P0_founder") -> P0_founder | Q10: =IFERROR(__xludf.DUMMYFUNCTION("""COMPUTED_VALUE"""),"male #23 - bright, low frequency transmission (<10%)") -> male #23 - bright, low frequency transmission (<10%) | R10: =IFERROR(__xludf.DUMMYFUNCTION("""COMPUTED_VALUE"""),"membrane") -> membrane | S10: =IFERROR(__xludf.DUMMYFUNCTION("""COMPUTED_VALUE"""),488) -> 488
A11: ef1a:2xLynk:tdmSG(J) (F1 of allele 306) | B11: =IFERROR(__xludf.DUMMYFUNCTION("IFERROR(JOIN("","", UNIQUE(filter({VLOOKUP(A11,C:X,13, FALSE); VLOOKUP(A11,C:X,15, FALSE); VLOOKUP(A11,C:X,17, FALSE); VLOOKUP(A11,C:X,19, FALSE)}, {VLOOKUP(A11,C:X,13, FALSE); VLOOKUP(A11,C:X,15, FALSE); VLOOKUP(A11,C:X,17, FALSE); VLOOKUP(A11,C:X,19, FA"&"LSE)}<>""""))), """")"),"csp,male #14 - need to recross?,488") -> csp,male #14 - need to recross?,488 | C11: =IF(ISBLANK(D11), F11, CONCATENATE(G11, " (", E11, " of allele ", K11, ")" )) -> ef1a:2xLynk:tdmSG(J) (F1 of allele 305) | D11: =IF(ISBLANK(K11), , CONCATENATE("(", E11, " of allele ", K11, ")")) -> (F1 of allele 305) | E11: =IFERROR(__xludf.DUMMYFUNCTION("IFERROR(REGEXEXTRACT(N11, ""F\d+""), ""F1"")"),"F1") -> F1 | F11: =IFERROR(__xludf.DUMMYFUNCTION("""COMPUTED_VALUE"""),"tandem mem:mStayGold") -> tandem mem:mStayGold | G11: =IFERROR(__xludf.DUMMYFUNCTION("""COMPUTED_VALUE"""),"ef1a:2xLynk:tdmSG(J)") -> ef1a:2xLynk:tdmSG(J) | H11: =IFERROR(__xludf.DUMMYFUNCTION("""COMPUTED_VALUE"""),45520) -> 45520 | I11: =IFERROR(__xludf.DUMMYFUNCTION("""COMPUTED_VALUE"""),"pDQM005") -> pDQM005 | J11: =IFERROR(__xludf.DUMMYFUNCTION("""COMPUTED_VALUE"""),"tol2") -> tol2 | K11: =IFERROR(__xludf.DUMMYFUNCTION("""COMPUTED_VALUE"""),305) -> 305 | L11: =IFERROR(__xludf.DUMMYFUNCTION("""COMPUTED_VALUE"""),"casper") -> casper | M11: =IFERROR(__xludf.DUMMYFUNCTION("""COMPUTED_VALUE"""),45610) -> 45610 | N11: =IFERROR(__xludf.DUMMYFUNCTION("""COMPUTED_VALUE"""),"csp") -> csp | O11: =IFERROR(__xludf.DUMMYFUNCTION("""COMPUTED_VALUE"""),"csp") -> csp | P11: =IFERROR(__xludf.DUMMYFUNCTION("""COMPUTED_VALUE"""),"P0_founder") -> P0_founder | Q11: =IFERROR(__xludf.DUMMYFUNCTION("""COMPUTED_VALUE"""),"male #26 - bright, low frequency transmission (<10%)") -> male #26 - bright, low frequency transmission (<10%) | R11: =IFERROR(__xludf.DUMMYFUNCTION("""COMPUTED_VALUE"""),"membrane") -> membrane | S11: =IFERROR(__xludf.DUMMYFUNCTION("""COMPUTED_VALUE"""),488) -> 488
A12: ef1a:2xLynk:tdmSG(J) (F1 of allele 307) | B12: =IFERROR(__xludf.DUMMYFUNCTION("IFERROR(JOIN("","", UNIQUE(filter({VLOOKUP(A12,C:X,13, FALSE); VLOOKUP(A12,C:X,15, FALSE); VLOOKUP(A12,C:X,17, FALSE); VLOOKUP(A12,C:X,19, FALSE)}, {VLOOKUP(A12,C:X,13, FALSE); VLOOKUP(A12,C:X,15, FALSE); VLOOKUP(A12,C:X,17, FALSE); VLOOKUP(A12,C:X,19, FA"&"LSE)}<>""""))), """")"),"csp,female B - maternal +, but low frequency transmission - zygotic allele not super bright?,488") -> csp,female B - maternal +, but low frequency transmission - zygotic allele not super bright?,488 | C12: =IF(ISBLANK(D12), F12, CONCATENATE(G12, " (", E12, " of allele ", K12, ")" )) -> ef1a:2xLynk:tdmSG(J) (F1 of allele 306) | D12: =IF(ISBLANK(K12), , CONCATENATE("(", E12, " of allele ", K12, ")")) -> (F1 of allele 306) | E12: =IFERROR(__xludf.DUMMYFUNCTION("IFERROR(REGEXEXTRACT(N12, ""F\d+""), ""F1"")"),"F1") -> F1 | F12: =IFERROR(__xludf.DUMMYFUNCTION("""COMPUTED_VALUE"""),"tandem mem:mStayGold") -> tandem mem:mStayGold | G12: =IFERROR(__xludf.DUMMYFUNCTION("""COMPUTED_VALUE"""),"ef1a:2xLynk:tdmSG(J)") -> ef1a:2xLynk:tdmSG(J) | H12: =IFERROR(__xludf.DUMMYFUNCTION("""COMPUTED_VALUE"""),45520) -> 45520 | I12: =IFERROR(__xludf.DUMMYFUNCTION("""COMPUTED_VALUE"""),"pDQM005") -> pDQM005 | J12: =IFERROR(__xludf.DUMMYFUNCTION("""COMPUTED_VALUE"""),"tol2") -> tol2 | K12: =IFERROR(__xludf.DUMMYFUNCTION("""COMPUTED_VALUE"""),306) -> 306 | L12: =IFERROR(__xludf.DUMMYFUNCTION("""COMPUTED_VALUE"""),"casper") -> casper | M12: =IFERROR(__xludf.DUMMYFUNCTION("""COMPUTED_VALUE"""),45610) -> 45610 | N12: =IFERROR(__xludf.DUMMYFUNCTION("""COMPUTED_VALUE"""),"csp") -> csp | O12: =IFERROR(__xludf.DUMMYFUNCTION("""COMPUTED_VALUE"""),"csp") -> csp | P12: =IFERROR(__xludf.DUMMYFUNCTION("""COMPUTED_VALUE"""),"P0_founder") -> P0_founder | Q12: =IFERROR(__xludf.DUMMYFUNCTION("""COMPUTED_VALUE"""),"male #14 - need to recross?") -> male #14 - need to recross? | R12: =IFERROR(__xludf.DUMMYFUNCTION("""COMPUTED_VALUE"""),"membrane") -> membrane | S12: =IFERROR(__xludf.DUMMYFUNCTION("""COMPUTED_VALUE"""),488) -> 488
A13: ef1a:2xLynk:tdmSG(J) (F1 of allele 308) | B13: =IFERROR(__xludf.DUMMYFUNCTION("IFERROR(JOIN("","", UNIQUE(filter({VLOOKUP(A13,C:X,13, FALSE); VLOOKUP(A13,C:X,15, FALSE); VLOOKUP(A13,C:X,17, FALSE); VLOOKUP(A13,C:X,19, FALSE)}, {VLOOKUP(A13,C:X,13, FALSE); VLOOKUP(A13,C:X,15, FALSE); VLOOKUP(A13,C:X,17, FALSE); VLOOKUP(A13,C:X,19, FA"&"LSE)}<>""""))), """")"),"csp,male #19 - bright, low frequency transmission (<10%),488") -> csp,male #19 - bright, low frequency transmission (<10%),488 | C13: =IF(ISBLANK(D13), F13, CONCATENATE(G13, " (", E13, " of allele ", K13, ")" )) -> ef1a:2xLynk:tdmSG(J) (F1 of allele 307) | D13: =IF(ISBLANK(K13), , CONCATENATE("(", E13, " of allele ", K13, ")")) -> (F1 of allele 307) | E13: =IFERROR(__xludf.DUMMYFUNCTION("IFERROR(REGEXEXTRACT(N13, ""F\d+""), ""F1"")"),"F1") -> F1 | F13: =IFERROR(__xludf.DUMMYFUNCTION("""COMPUTED_VALUE"""),"tandem mem:mStayGold") -> tandem mem:mStayGold | G13: =IFERROR(__xludf.DUMMYFUNCTION("""COMPUTED_VALUE"""),"ef1a:2xLynk:tdmSG(J)") -> ef1a:2xLynk:tdmSG(J) | H13: =IFERROR(__xludf.DUMMYFUNCTION("""COMPUTED_VALUE"""),45520) -> 45520 | I13: =IFERROR(__xludf.DUMMYFUNCTION("""COMPUTED_VALUE"""),"pDQM005") -> pDQM005 | J13: =IFERROR(__xludf.DUMMYFUNCTION("""COMPUTED_VALUE"""),"tol2") -> tol2 | K13: =IFERROR(__xludf.DUMMYFUNCTION("""COMPUTED_VALUE"""),307) -> 307 | L13: =IFERROR(__xludf.DUMMYFUNCTION("""COMPUTED_VALUE"""),"casper") -> casper | M13: =IFERROR(__xludf.DUMMYFUNCTION("""COMPUTED_VALUE"""),45610) -> 45610 | N13: =IFERROR(__xludf.DUMMYFUNCTION("""COMPUTED_VALUE"""),"csp") -> csp | O13: =IFERROR(__xludf.DUMMYFUNCTION("""COMPUTED_VALUE"""),"csp") -> csp | P13: =IFERROR(__xludf.DUMMYFUNCTION("""COMPUTED_VALUE"""),"P0_founder") -> P0_founder | Q13: =IFERROR(__xludf.DUMMYFUNCTION("""COMPUTED_VALUE"""),"female B - maternal +, but low frequency transmission - zygotic allele not super bright?") -> female B - maternal +, but low frequency transmission - zygotic allele not super bright? | R13: =IFERROR(__xludf.DUMMYFUNCTION("""COMPUTED_VALUE"""),"membrane") -> membrane | S13: =IFERROR(__xludf.DUMMYFUNCTION("""COMPUTED_VALUE"""),488) -> 488
A14: ef1a:<cryaa:mSc>mKate2/mCitrine/Electra2/mKOK/mTFP1 (F1 of allele 309) | B14: =IFERROR(__xludf.DUMMYFUNCTION("IFERROR(JOIN("","", UNIQUE(filter({VLOOKUP(A14,C:X,13, FALSE); VLOOKUP(A14,C:X,15, FALSE); VLOOKUP(A14,C:X,17, FALSE); VLOOKUP(A14,C:X,19, FALSE)}, {VLOOKUP(A14,C:X,13, FALSE); VLOOKUP(A14,C:X,15, FALSE); VLOOKUP(A14,C:X,17, FALSE); VLOOKUP(A14,C:X,19, FA"&"LSE)}<>""""))), """")"),"csp,male #5 25%+ positive rate - currently best founder (but 2 alleles, one dim one bright(er)?,405,445") -> csp,male #5 25%+ positive rate - currently best founder (but 2 alleles, one dim one bright(er)?,405,445 | C14: =IF(ISBLANK(D14), F14, CONCATENATE(G14, " (", E14, " of allele ", K14, ")" )) -> ef1a:2xLynk:tdmSG(J) (F1 of allele 308) | D14: =IF(ISBLANK(K14), , CONCATENATE("(", E14, " of allele ", K14, ")")) -> (F1 of allele 308) | E14: =IFERROR(__xludf.DUMMYFUNCTION("IFERROR(REGEXEXTRACT(N14, ""F\d+""), ""F1"")"),"F1") -> F1 | F14: =IFERROR(__xludf.DUMMYFUNCTION("""COMPUTED_VALUE"""),"tandem mem:mStayGold") -> tandem mem:mStayGold | G14: =IFERROR(__xludf.DUMMYFUNCTION("""COMPUTED_VALUE"""),"ef1a:2xLynk:tdmSG(J)") -> ef1a:2xLynk:tdmSG(J) | H14: =IFERROR(__xludf.DUMMYFUNCTION("""COMPUTED_VALUE"""),45520) -> 45520 | I14: =IFERROR(__xludf.DUMMYFUNCTION("""COMPUTED_VALUE"""),"pDQM005") -> pDQM005 | J14: =IFERROR(__xludf.DUMMYFUNCTION("""COMPUTED_VALUE"""),"tol2") -> tol2 | K14: =IFERROR(__xludf.DUMMYFUNCTION("""COMPUTED_VALUE"""),308) -> 308 | L14: =IFERROR(__xludf.DUMMYFUNCTION("""COMPUTED_VALUE"""),"casper") -> casper | M14: =IFERROR(__xludf.DUMMYFUNCTION("""COMPUTED_VALUE"""),45610) -> 45610 | N14: =IFERROR(__xludf.DUMMYFUNCTION("""COMPUTED_VALUE"""),"csp") -> csp | O14: =IFERROR(__xludf.DUMMYFUNCTION("""COMPUTED_VALUE"""),"csp") -> csp | P14: =IFERROR(__xludf.DUMMYFUNCTION("""COMPUTED_VALUE"""),"P0_founder") -> P0_founder | Q14: =IFERROR(__xludf.DUMMYFUNCTION("""COMPUTED_VALUE"""),"male #19 - bright, low frequency transmission (<10%)") -> male #19 - bright, low frequency transmission (<10%) | R14: =IFERROR(__xludf.DUMMYFUNCTION("""COMPUTED_VALUE"""),"membrane") -> membrane | S14: =IFERROR(__xludf.DUMMYFUNCTION("""COMPUTED_VALUE"""),488) -> 488
A15: ef1a:<cryaa:mSc>mKate2/mCitrine/Electra2/mKOK/mTFP1 (F1 of allele 310) | B15: =IFERROR(__xludf.DUMMYFUNCTION("IFERROR(JOIN("","", UNIQUE(filter({VLOOKUP(A15,C:X,13, FALSE); VLOOKUP(A15,C:X,15, FALSE); VLOOKUP(A15,C:X,17, FALSE); VLOOKUP(A15,C:X,19, FALSE)}, {VLOOKUP(A15,C:X,13, FALSE); VLOOKUP(A15,C:X,15, FALSE); VLOOKUP(A15,C:X,17, FALSE); VLOOKUP(A15,C:X,19, FA"&"LSE)}<>""""))), """")"),"310,male #11 ~20% positive rate,405,445") -> 310,male #11 ~20% positive rate,405,445 | C15: =IF(ISBLANK(D15), F15, CONCATENATE(G15, " (", E15, " of allele ", K15, ")" )) -> ef1a:<cryaa:mSc>mKate2/mCitrine/Electra2/mKOK/mTFP1 (F1 of allele 309) | D15: =IF(ISBLANK(K15), , CONCATENATE("(", E15, " of allele ", K15, ")")) -> (F1 of allele 309) | E15: =IFERROR(__xludf.DUMMYFUNCTION("IFERROR(REGEXEXTRACT(N15, ""F\d+""), ""F1"")"),"F1") -> F1 | F15: =IFERROR(__xludf.DUMMYFUNCTION("""COMPUTED_VALUE"""),"Skittles 5 FP cryaa:mScarlet") -> Skittles 5 FP cryaa:mScarlet | G15: =IFERROR(__xludf.DUMMYFUNCTION("""COMPUTED_VALUE"""),"ef1a:<cryaa:mSc>mKate2/mCitrine/Electra2/mKOK/mTFP1") -> ef1a:<cryaa:mSc>mKate2/mCitrine/Electra2/mKOK/mTFP1 | H15: =IFERROR(__xludf.DUMMYFUNCTION("""COMPUTED_VALUE"""),45566) -> 45566 | I15: =IFERROR(__xludf.DUMMYFUNCTION("""COMPUTED_VALUE"""),"pDQM034/035") -> pDQM034/035 | J15: =IFERROR(__xludf.DUMMYFUNCTION("""COMPUTED_VALUE"""),"tol2") -> tol2 | K15: =IFERROR(__xludf.DUMMYFUNCTION("""COMPUTED_VALUE"""),309) -> 309 | L15: =IFERROR(__xludf.DUMMYFUNCTION("""COMPUTED_VALUE"""),"casper") -> casper | N15: =IFERROR(__xludf.DUMMYFUNCTION("""COMPUTED_VALUE"""),"csp") -> csp | O15: =IFERROR(__xludf.DUMMYFUNCTION("""COMPUTED_VALUE"""),"csp") -> csp | P15: =IFERROR(__xludf.DUMMYFUNCTION("""COMPUTED_VALUE"""),"P0_founder") -> P0_founder | Q15: =IFERROR(__xludf.DUMMYFUNCTION("""COMPUTED_VALUE"""),"male #5 25%+ positive rate - currently best founder (but 2 alleles, one dim one bright(er)?") -> male #5 25%+ positive rate - currently best founder (but 2 alleles, one dim one bright(er)? | R15: =IFERROR(__xludf.DUMMYFUNCTION("""COMPUTED_VALUE"""),"cytosol") -> cytosol | S15: =IFERROR(__xludf.DUMMYFUNCTION("""COMPUTED_VALUE"""),405) -> 405 | T15: =IFERROR(__xludf.DUMMYFUNCTION("""COMPUTED_VALUE"""),"cytosol") -> cytosol | U15: =IFERROR(__xludf.DUMMYFUNCTION("""COMPUTED_VALUE"""),445) -> 445 | V15: =IFERROR(__xludf.DUMMYFUNCTION("""COMPUTED_VALUE"""),"cytosol") -> cytosol | W15: =IFERROR(__xludf.DUMMYFUNCTION("""COMPUTED_VALUE"""),514) -> 514 | X15: =IFERROR(__xludf.DUMMYFUNCTION("""COMPUTED_VALUE"""),"cytosol") -> cytosol
A16: ef1a:<exorh:GFP>mKate2/mCitrine/Electra2/mKOK/mTFP1 (F1 of allele 311) | B16: =IFERROR(__xludf.DUMMYFUNCTION("IFERROR(JOIN("","", UNIQUE(filter({VLOOKUP(A16,C:X,13, FALSE); VLOOKUP(A16,C:X,15, FALSE); VLOOKUP(A16,C:X,17, FALSE); VLOOKUP(A16,C:X,19, FALSE)}, {VLOOKUP(A16,C:X,13, FALSE); VLOOKUP(A16,C:X,15, FALSE); VLOOKUP(A16,C:X,17, FALSE); VLOOKUP(A16,C:X,19, FA"&"LSE)}<>""""))), """")"),"csp,female - low frequency (1-2%) exorH:GFP (+) embryos - will start tank 311,405,445") -> csp,female - low frequency (1-2%) exorH:GFP (+) embryos - will start tank 311,405,445 | C16: =IF(ISBLANK(D16), F16, CONCATENATE(G16, " (", E16, " of allele ", K16, ")" )) -> ef1a:<cryaa:mSc>mKate2/mCitrine/Electra2/mKOK/mTFP1 (F1 of allele 309) | D16: =IF(ISBLANK(K16), , CONCATENATE("(", E16, " of allele ", K16, ")")) -> (F1 of allele 309) | E16: =IFERROR(__xludf.DUMMYFUNCTION("IFERROR(REGEXEXTRACT(N16, ""F\d+""), ""F1"")"),"F1") -> F1 | F16: =IFERROR(__xludf.DUMMYFUNCTION("""COMPUTED_VALUE"""),"Abe") -> Abe | G16: =IFERROR(__xludf.DUMMYFUNCTION("""COMPUTED_VALUE"""),"ef1a:<cryaa:mSc>mKate2/mCitrine/Electra2/mKOK/mTFP1") -> ef1a:<cryaa:mSc>mKate2/mCitrine/Electra2/mKOK/mTFP1 | H16: =IFERROR(__xludf.DUMMYFUNCTION("""COMPUTED_VALUE"""),45566) -> 45566 | I16: =IFERROR(__xludf.DUMMYFUNCTION("""COMPUTED_VALUE"""),"pDQM034/035") -> pDQM034/035 | J16: =IFERROR(__xludf.DUMMYFUNCTION("""COMPUTED_VALUE"""),"tol2") -> tol2 | K16: =IFERROR(__xludf.DUMMYFUNCTION("""COMPUTED_VALUE"""),309) -> 309 | L16: =IFERROR(__xludf.DUMMYFUNCTION("""COMPUTED_VALUE"""),"casper") -> casper | N16: =IFERROR(__xludf.DUMMYFUNCTION("""COMPUTED_VALUE"""),"csp") -> csp | O16: =IFERROR(__xludf.DUMMYFUNCTION("""COMPUTED_VALUE"""),"csp") -> csp | P16: =IFERROR(__xludf.DUMMYFUNCTION("""COMPUTED_VALUE"""),"P0_founder") -> P0_founder | Q16: =IFERROR(__xludf.DUMMYFUNCTION("""COMPUTED_VALUE"""),"male #5 25%+ positive rate - currently best founder (but 2 alleles, one dim one bright(er)?") -> male #5 25%+ positive rate - currently best founder (but 2 alleles, one dim one bright(er)? | R16: =IFERROR(__xludf.DUMMYFUNCTION("""COMPUTED_VALUE"""),"cytosol") -> cytosol | S16: =IFERROR(__xludf.DUMMYFUNCTION("""COMPUTED_VALUE"""),405) -> 405 | T16: =IFERROR(__xludf.DUMMYFUNCTION("""COMPUTED_VALUE"""),"cytosol") -> cytosol | U16: =IFERROR(__xludf.DUMMYFUNCTION("""COMPUTED_VALUE"""),445) -> 445 | V16: =IFERROR(__xludf.DUMMYFUNCTION("""COMPUTED_VALUE"""),"cytosol") -> cytosol | W16: =IFERROR(__xludf.DUMMYFUNCTION("""COMPUTED_VALUE"""),514) -> 514 | X16: =IFERROR(__xludf.DUMMYFUNCTION("""COMPUTED_VALUE"""),"cytosol") -> cytosol
A17: ef1a:<exorh:GFP>mKate2/mCitrine/Electra2/mKOK/mTFP1 (F1 of allele 312) | B17: =IFERROR(__xludf.DUMMYFUNCTION("IFERROR(JOIN("","", UNIQUE(filter({VLOOKUP(A17,C:X,13, FALSE); VLOOKUP(A17,C:X,15, FALSE); VLOOKUP(A17,C:X,17, FALSE); VLOOKUP(A17,C:X,19, FALSE)}, {VLOOKUP(A17,C:X,13, FALSE); VLOOKUP(A17,C:X,15, FALSE); VLOOKUP(A17,C:X,17, FALSE); VLOOKUP(A17,C:X,19, FA"&"LSE)}<>""""))), """")"),"csp,female - low frequency (1-2%) exorH:GFP (+) embryos - will start tank 311,405,445") -> csp,female - low frequency (1-2%) exorH:GFP (+) embryos - will start tank 311,405,445 | C17: =IF(ISBLANK(D17), F17, CONCATENATE(G17, " (", E17, " of allele ", K17, ")" )) -> ef1a:<cryaa:mSc>mKate2/mCitrine/Electra2/mKOK/mTFP1 (F1 of allele 309) | D17: =IF(ISBLANK(K17), , CONCATENATE("(", E17, " of allele ", K17, ")")) -> (F1 of allele 309) | E17: =IFERROR(__xludf.DUMMYFUNCTION("IFERROR(REGEXEXTRACT(N17, ""F\d+""), ""F1"")"),"F1") -> F1 | F17: =IFERROR(__xludf.DUMMYFUNCTION("""COMPUTED_VALUE"""),"Skittles 5 FP cryaa:mScarlet") -> Skittles 5 FP cryaa:mScarlet | G17: =IFERROR(__xludf.DUMMYFUNCTION("""COMPUTED_VALUE"""),"ef1a:<cryaa:mSc>mKate2/mCitrine/Electra2/mKOK/mTFP1") -> ef1a:<cryaa:mSc>mKate2/mCitrine/Electra2/mKOK/mTFP1 | H17: =IFERROR(__xludf.DUMMYFUNCTION("""COMPUTED_VALUE"""),45566) -> 45566 | I17: =IFERROR(__xludf.DUMMYFUNCTION("""COMPUTED_VALUE"""),"pDQM034/035") -> pDQM034/035 | J17: =IFERROR(__xludf.DUMMYFUNCTION("""COMPUTED_VALUE"""),"tol2") -> tol2 | K17: =IFERROR(__xludf.DUMMYFUNCTION("""COMPUTED_VALUE"""),309) -> 309 | L17: =IFERROR(__xludf.DUMMYFUNCTION("""COMPUTED_VALUE"""),"casper") -> casper | N17: =IFERROR(__xludf.DUMMYFUNCTION("""COMPUTED_VALUE"""),"csp") -> csp | O17: =IFERROR(__xludf.DUMMYFUNCTION("""COMPUTED_VALUE"""),309) -> 309 | P17: =IFERROR(__xludf.DUMMYFUNCTION("""COMPUTED_VALUE"""),"F1_ox") -> F1_ox | Q17: =IFERROR(__xludf.DUMMYFUNCTION("""COMPUTED_VALUE"""),"F1s of male #5 (~6 fish, multiple alleles, need to determine which ones are carrying the better allele)") -> F1s of male #5 (~6 fish, multiple alleles, need to determine which ones are carrying the better allele) | R17: =IFERROR(__xludf.DUMMYFUNCTION("""COMPUTED_VALUE"""),"cytosol") -> cytosol | S17: =IFERROR(__xludf.DUMMYFUNCTION("""COMPUTED_VALUE"""),405) -> 405 | T17: =IFERROR(__xludf.DUMMYFUNCTION("""COMPUTED_VALUE"""),"cytosol") -> cytosol | U17: =IFERROR(__xludf.DUMMYFUNCTION("""COMPUTED_VALUE"""),445) -> 445 | V17: =IFERROR(__xludf.DUMMYFUNCTION("""COMPUTED_VALUE"""),"cytosol") -> cytosol | W17: =IFERROR(__xludf.DUMMYFUNCTION("""COMPUTED_VALUE"""),514) -> 514 | X17: =IFERROR(__xludf.DUMMYFUNCTION("""COMPUTED_VALUE"""),"cytosol") -> cytosol
